2020-01-11 22:30:19,585 ERROR: Exception on /index [GET] [in /Users/AlexYang/anaconda3/lib/python3.6/site-packages/flask/app.py:1761]
Traceback (most recent call last):
  File "/Users/AlexYang/anaconda3/lib/python3.6/site-packages/flask/app.py", line 2292, in wsgi_app
    response = self.full_dispatch_request()
  File "/Users/AlexYang/anaconda3/lib/python3.6/site-packages/flask/app.py", line 1815, in full_dispatch_request
    rv = self.handle_user_exception(e)
  File "/Users/AlexYang/anaconda3/lib/python3.6/site-packages/flask/app.py", line 1718, in handle_user_exception
    reraise(exc_type, exc_value, tb)
  File "/Users/AlexYang/anaconda3/lib/python3.6/site-packages/flask/_compat.py", line 35, in reraise
    raise value
  File "/Users/AlexYang/anaconda3/lib/python3.6/site-packages/flask/app.py", line 1813, in full_dispatch_request
    rv = self.dispatch_request()
  File "/Users/AlexYang/anaconda3/lib/python3.6/site-packages/flask/app.py", line 1799, in dispatch_request
    return self.view_functions[rule.endpoint](**req.view_args)
  File "/Users/AlexYang/anaconda3/lib/python3.6/site-packages/flask_login/utils.py", line 261, in decorated_view
    return func(*args, **kwargs)
  File "/Users/AlexYang/mt.rainier-form/app/main/routes.py", line 52, in index
    return render_template('index.html', title='Patient Registration', form=f)
  File "/Users/AlexYang/anaconda3/lib/python3.6/site-packages/flask/templating.py", line 135, in render_template
    context, ctx.app)
  File "/Users/AlexYang/anaconda3/lib/python3.6/site-packages/flask/templating.py", line 117, in _render
    rv = template.render(context)
  File "/Users/AlexYang/anaconda3/lib/python3.6/site-packages/jinja2/asyncsupport.py", line 76, in render
    return original_render(self, *args, **kwargs)
  File "/Users/AlexYang/anaconda3/lib/python3.6/site-packages/jinja2/environment.py", line 1008, in render
    return self.environment.handle_exception(exc_info, True)
  File "/Users/AlexYang/anaconda3/lib/python3.6/site-packages/jinja2/environment.py", line 780, in handle_exception
    reraise(exc_type, exc_value, tb)
  File "/Users/AlexYang/anaconda3/lib/python3.6/site-packages/jinja2/_compat.py", line 37, in reraise
    raise value.with_traceback(tb)
  File "/Users/AlexYang/mt.rainier-form/app/templates/base.html", line 41, in template
    {% endblock %}
  File "/Users/AlexYang/anaconda3/lib/python3.6/site-packages/jinja2/environment.py", line 1005, in render
    return concat(self.root_render_func(self.new_context(vars)))
  File "/Users/AlexYang/mt.rainier-form/app/templates/index.html", line 1, in top-level template code
    {% extends "base.html" %}
  File "/Users/AlexYang/anaconda3/lib/python3.6/site-packages/jinja2/environment.py", line 780, in handle_exception
    reraise(exc_type, exc_value, tb)
  File "/Users/AlexYang/anaconda3/lib/python3.6/site-packages/jinja2/_compat.py", line 37, in reraise
    raise value.with_traceback(tb)
  File "/Users/AlexYang/mt.rainier-form/app/templates/base.html", line 41, in template
    {% endblock %}
  File "/Users/AlexYang/anaconda3/lib/python3.6/site-packages/jinja2/environment.py", line 497, in _parse
    return Parser(self, source, name, encode_filename(filename)).parse()
  File "/Users/AlexYang/anaconda3/lib/python3.6/site-packages/jinja2/parser.py", line 901, in parse
    result = nodes.Template(self.subparse(), lineno=1)
  File "/Users/AlexYang/anaconda3/lib/python3.6/site-packages/jinja2/parser.py", line 883, in subparse
    rv = self.parse_statement()
  File "/Users/AlexYang/anaconda3/lib/python3.6/site-packages/jinja2/parser.py", line 130, in parse_statement
    return getattr(self, 'parse_' + self.stream.current.value)()
  File "/Users/AlexYang/anaconda3/lib/python3.6/site-packages/jinja2/parser.py", line 268, in parse_block
    node.body = self.parse_statements(('name:endblock',), drop_needle=True)
  File "/Users/AlexYang/anaconda3/lib/python3.6/site-packages/jinja2/parser.py", line 165, in parse_statements
    result = self.subparse(end_tokens)
  File "/Users/AlexYang/anaconda3/lib/python3.6/site-packages/jinja2/parser.py", line 883, in subparse
    rv = self.parse_statement()
  File "/Users/AlexYang/anaconda3/lib/python3.6/site-packages/jinja2/parser.py", line 130, in parse_statement
    return getattr(self, 'parse_' + self.stream.current.value)()
  File "/Users/AlexYang/anaconda3/lib/python3.6/site-packages/jinja2/parser.py", line 223, in parse_if
    drop_needle=True)
  File "/Users/AlexYang/anaconda3/lib/python3.6/site-packages/jinja2/parser.py", line 165, in parse_statements
    result = self.subparse(end_tokens)
  File "/Users/AlexYang/anaconda3/lib/python3.6/site-packages/jinja2/parser.py", line 883, in subparse
    rv = self.parse_statement()
  File "/Users/AlexYang/anaconda3/lib/python3.6/site-packages/jinja2/parser.py", line 144, in parse_statement
    self.fail_unknown_tag(token.value, token.lineno)
  File "/Users/AlexYang/anaconda3/lib/python3.6/site-packages/jinja2/parser.py", line 97, in fail_unknown_tag
    return self._fail_ut_eof(name, self._end_token_stack, lineno)
  File "/Users/AlexYang/anaconda3/lib/python3.6/site-packages/jinja2/parser.py", line 90, in _fail_ut_eof
    self.fail(' '.join(message), lineno)
  File "/Users/AlexYang/anaconda3/lib/python3.6/site-packages/jinja2/parser.py", line 59, in fail
    raise exc(msg, lineno, self.name, self.filename)
jinja2.exceptions.TemplateSyntaxError: Encountered unknown tag 'endblock'. You probably made a nesting mistake. Jinja is expecting this tag, but currently looking for 'endif'. The innermost block that needs to be closed is 'if'.
2020-01-11 22:30:41,350 INFO: Mt Rainier startup [in /Users/AlexYang/mt.rainier-form/app/__init__.py:52]
2020-01-11 22:31:03,452 INFO: Mt Rainier startup [in /Users/AlexYang/mt.rainier-form/app/__init__.py:52]
2020-01-11 22:31:07,710 ERROR: Exception on /followup [GET] [in /Users/AlexYang/anaconda3/lib/python3.6/site-packages/flask/app.py:1761]
Traceback (most recent call last):
  File "/Users/AlexYang/anaconda3/lib/python3.6/site-packages/flask/app.py", line 2292, in wsgi_app
    response = self.full_dispatch_request()
  File "/Users/AlexYang/anaconda3/lib/python3.6/site-packages/flask/app.py", line 1815, in full_dispatch_request
    rv = self.handle_user_exception(e)
  File "/Users/AlexYang/anaconda3/lib/python3.6/site-packages/flask/app.py", line 1718, in handle_user_exception
    reraise(exc_type, exc_value, tb)
  File "/Users/AlexYang/anaconda3/lib/python3.6/site-packages/flask/_compat.py", line 35, in reraise
    raise value
  File "/Users/AlexYang/anaconda3/lib/python3.6/site-packages/flask/app.py", line 1813, in full_dispatch_request
    rv = self.dispatch_request()
  File "/Users/AlexYang/anaconda3/lib/python3.6/site-packages/flask/app.py", line 1799, in dispatch_request
    return self.view_functions[rule.endpoint](**req.view_args)
  File "/Users/AlexYang/anaconda3/lib/python3.6/site-packages/flask_login/utils.py", line 261, in decorated_view
    return func(*args, **kwargs)
  File "/Users/AlexYang/mt.rainier-form/app/main/routes.py", line 71, in followup
    f = FollowUpForm()
NameError: name 'FollowUpForm' is not defined
2020-01-11 22:32:05,443 INFO: Mt Rainier startup [in /Users/AlexYang/mt.rainier-form/app/__init__.py:52]
2020-01-11 22:32:07,450 ERROR: Exception on /followup [GET] [in /Users/AlexYang/anaconda3/lib/python3.6/site-packages/flask/app.py:1761]
Traceback (most recent call last):
  File "/Users/AlexYang/anaconda3/lib/python3.6/site-packages/flask/app.py", line 2292, in wsgi_app
    response = self.full_dispatch_request()
  File "/Users/AlexYang/anaconda3/lib/python3.6/site-packages/flask/app.py", line 1815, in full_dispatch_request
    rv = self.handle_user_exception(e)
  File "/Users/AlexYang/anaconda3/lib/python3.6/site-packages/flask/app.py", line 1718, in handle_user_exception
    reraise(exc_type, exc_value, tb)
  File "/Users/AlexYang/anaconda3/lib/python3.6/site-packages/flask/_compat.py", line 35, in reraise
    raise value
  File "/Users/AlexYang/anaconda3/lib/python3.6/site-packages/flask/app.py", line 1813, in full_dispatch_request
    rv = self.dispatch_request()
  File "/Users/AlexYang/anaconda3/lib/python3.6/site-packages/flask/app.py", line 1799, in dispatch_request
    return self.view_functions[rule.endpoint](**req.view_args)
  File "/Users/AlexYang/anaconda3/lib/python3.6/site-packages/flask_login/utils.py", line 261, in decorated_view
    return func(*args, **kwargs)
  File "/Users/AlexYang/mt.rainier-form/app/main/routes.py", line 71, in followup
    f = FollowUpForm()
NameError: name 'FollowUpForm' is not defined
2020-01-11 22:32:09,504 ERROR: Exception on /followup [GET] [in /Users/AlexYang/anaconda3/lib/python3.6/site-packages/flask/app.py:1761]
Traceback (most recent call last):
  File "/Users/AlexYang/anaconda3/lib/python3.6/site-packages/flask/app.py", line 2292, in wsgi_app
    response = self.full_dispatch_request()
  File "/Users/AlexYang/anaconda3/lib/python3.6/site-packages/flask/app.py", line 1815, in full_dispatch_request
    rv = self.handle_user_exception(e)
  File "/Users/AlexYang/anaconda3/lib/python3.6/site-packages/flask/app.py", line 1718, in handle_user_exception
    reraise(exc_type, exc_value, tb)
  File "/Users/AlexYang/anaconda3/lib/python3.6/site-packages/flask/_compat.py", line 35, in reraise
    raise value
  File "/Users/AlexYang/anaconda3/lib/python3.6/site-packages/flask/app.py", line 1813, in full_dispatch_request
    rv = self.dispatch_request()
  File "/Users/AlexYang/anaconda3/lib/python3.6/site-packages/flask/app.py", line 1799, in dispatch_request
    return self.view_functions[rule.endpoint](**req.view_args)
  File "/Users/AlexYang/anaconda3/lib/python3.6/site-packages/flask_login/utils.py", line 261, in decorated_view
    return func(*args, **kwargs)
  File "/Users/AlexYang/mt.rainier-form/app/main/routes.py", line 71, in followup
    f = FollowUpForm()
NameError: name 'FollowUpForm' is not defined
2020-01-11 22:32:59,179 INFO: Mt Rainier startup [in /Users/AlexYang/mt.rainier-form/app/__init__.py:52]
2020-01-11 22:33:04,513 INFO: Mt Rainier startup [in /Users/AlexYang/mt.rainier-form/app/__init__.py:52]
