2020-01-16 14:17:24,981 ERROR: Exception on /admin/patient follow-ups/ [GET] [in /Users/AlexYang/anaconda3/lib/python3.6/site-packages/flask/app.py:1761]
Traceback (most recent call last):
  File "/Users/AlexYang/anaconda3/lib/python3.6/site-packages/flask/app.py", line 2292, in wsgi_app
    response = self.full_dispatch_request()
  File "/Users/AlexYang/anaconda3/lib/python3.6/site-packages/flask/app.py", line 1815, in full_dispatch_request
    rv = self.handle_user_exception(e)
  File "/Users/AlexYang/anaconda3/lib/python3.6/site-packages/flask/app.py", line 1718, in handle_user_exception
    reraise(exc_type, exc_value, tb)
  File "/Users/AlexYang/anaconda3/lib/python3.6/site-packages/flask/_compat.py", line 35, in reraise
    raise value
  File "/Users/AlexYang/anaconda3/lib/python3.6/site-packages/flask/app.py", line 1813, in full_dispatch_request
    rv = self.dispatch_request()
  File "/Users/AlexYang/anaconda3/lib/python3.6/site-packages/flask/app.py", line 1799, in dispatch_request
    return self.view_functions[rule.endpoint](**req.view_args)
  File "/Users/AlexYang/anaconda3/lib/python3.6/site-packages/flask_admin/base.py", line 69, in inner
    return self._run_view(f, *args, **kwargs)
  File "/Users/AlexYang/anaconda3/lib/python3.6/site-packages/flask_admin/base.py", line 368, in _run_view
    return fn(self, *args, **kwargs)
TypeError: index() takes 0 positional arguments but 1 was given
2020-01-16 14:18:07,752 INFO: Mt Rainier startup [in /Users/AlexYang/mt.rainier-form/app/__init__.py:56]
2020-01-16 14:18:11,950 ERROR: Exception on /admin/patient follow-ups/ [GET] [in /Users/AlexYang/anaconda3/lib/python3.6/site-packages/flask/app.py:1761]
Traceback (most recent call last):
  File "/Users/AlexYang/anaconda3/lib/python3.6/site-packages/flask/app.py", line 2292, in wsgi_app
    response = self.full_dispatch_request()
  File "/Users/AlexYang/anaconda3/lib/python3.6/site-packages/flask/app.py", line 1815, in full_dispatch_request
    rv = self.handle_user_exception(e)
  File "/Users/AlexYang/anaconda3/lib/python3.6/site-packages/flask/app.py", line 1718, in handle_user_exception
    reraise(exc_type, exc_value, tb)
  File "/Users/AlexYang/anaconda3/lib/python3.6/site-packages/flask/_compat.py", line 35, in reraise
    raise value
  File "/Users/AlexYang/anaconda3/lib/python3.6/site-packages/flask/app.py", line 1813, in full_dispatch_request
    rv = self.dispatch_request()
  File "/Users/AlexYang/anaconda3/lib/python3.6/site-packages/flask/app.py", line 1799, in dispatch_request
    return self.view_functions[rule.endpoint](**req.view_args)
  File "/Users/AlexYang/anaconda3/lib/python3.6/site-packages/flask_admin/base.py", line 69, in inner
    return self._run_view(f, *args, **kwargs)
  File "/Users/AlexYang/anaconda3/lib/python3.6/site-packages/flask_admin/base.py", line 368, in _run_view
    return fn(self, *args, **kwargs)
TypeError: index() takes 0 positional arguments but 1 was given
2020-01-16 14:18:18,227 ERROR: Exception on /admin/patient registration/ [GET] [in /Users/AlexYang/anaconda3/lib/python3.6/site-packages/flask/app.py:1761]
Traceback (most recent call last):
  File "/Users/AlexYang/anaconda3/lib/python3.6/site-packages/flask/app.py", line 2292, in wsgi_app
    response = self.full_dispatch_request()
  File "/Users/AlexYang/anaconda3/lib/python3.6/site-packages/flask/app.py", line 1815, in full_dispatch_request
    rv = self.handle_user_exception(e)
  File "/Users/AlexYang/anaconda3/lib/python3.6/site-packages/flask/app.py", line 1718, in handle_user_exception
    reraise(exc_type, exc_value, tb)
  File "/Users/AlexYang/anaconda3/lib/python3.6/site-packages/flask/_compat.py", line 35, in reraise
    raise value
  File "/Users/AlexYang/anaconda3/lib/python3.6/site-packages/flask/app.py", line 1813, in full_dispatch_request
    rv = self.dispatch_request()
  File "/Users/AlexYang/anaconda3/lib/python3.6/site-packages/flask/app.py", line 1799, in dispatch_request
    return self.view_functions[rule.endpoint](**req.view_args)
  File "/Users/AlexYang/anaconda3/lib/python3.6/site-packages/flask_admin/base.py", line 69, in inner
    return self._run_view(f, *args, **kwargs)
  File "/Users/AlexYang/anaconda3/lib/python3.6/site-packages/flask_admin/base.py", line 368, in _run_view
    return fn(self, *args, **kwargs)
TypeError: index() takes 0 positional arguments but 1 was given
2020-01-16 14:18:31,937 INFO: Mt Rainier startup [in /Users/AlexYang/mt.rainier-form/app/__init__.py:56]
2020-01-16 14:18:39,610 ERROR: Exception on /admin/patient registration/ [GET] [in /Users/AlexYang/anaconda3/lib/python3.6/site-packages/flask/app.py:1761]
Traceback (most recent call last):
  File "/Users/AlexYang/anaconda3/lib/python3.6/site-packages/flask/app.py", line 2292, in wsgi_app
    response = self.full_dispatch_request()
  File "/Users/AlexYang/anaconda3/lib/python3.6/site-packages/flask/app.py", line 1815, in full_dispatch_request
    rv = self.handle_user_exception(e)
  File "/Users/AlexYang/anaconda3/lib/python3.6/site-packages/flask/app.py", line 1718, in handle_user_exception
    reraise(exc_type, exc_value, tb)
  File "/Users/AlexYang/anaconda3/lib/python3.6/site-packages/flask/_compat.py", line 35, in reraise
    raise value
  File "/Users/AlexYang/anaconda3/lib/python3.6/site-packages/flask/app.py", line 1813, in full_dispatch_request
    rv = self.dispatch_request()
  File "/Users/AlexYang/anaconda3/lib/python3.6/site-packages/flask/app.py", line 1799, in dispatch_request
    return self.view_functions[rule.endpoint](**req.view_args)
  File "/Users/AlexYang/anaconda3/lib/python3.6/site-packages/flask_admin/base.py", line 69, in inner
    return self._run_view(f, *args, **kwargs)
  File "/Users/AlexYang/anaconda3/lib/python3.6/site-packages/flask_admin/base.py", line 368, in _run_view
    return fn(self, *args, **kwargs)
TypeError: index() takes 0 positional arguments but 1 was given
2020-01-16 14:18:44,633 ERROR: Exception on /admin/patient follow-ups/ [GET] [in /Users/AlexYang/anaconda3/lib/python3.6/site-packages/flask/app.py:1761]
Traceback (most recent call last):
  File "/Users/AlexYang/anaconda3/lib/python3.6/site-packages/flask/app.py", line 2292, in wsgi_app
    response = self.full_dispatch_request()
  File "/Users/AlexYang/anaconda3/lib/python3.6/site-packages/flask/app.py", line 1815, in full_dispatch_request
    rv = self.handle_user_exception(e)
  File "/Users/AlexYang/anaconda3/lib/python3.6/site-packages/flask/app.py", line 1718, in handle_user_exception
    reraise(exc_type, exc_value, tb)
  File "/Users/AlexYang/anaconda3/lib/python3.6/site-packages/flask/_compat.py", line 35, in reraise
    raise value
  File "/Users/AlexYang/anaconda3/lib/python3.6/site-packages/flask/app.py", line 1813, in full_dispatch_request
    rv = self.dispatch_request()
  File "/Users/AlexYang/anaconda3/lib/python3.6/site-packages/flask/app.py", line 1799, in dispatch_request
    return self.view_functions[rule.endpoint](**req.view_args)
  File "/Users/AlexYang/anaconda3/lib/python3.6/site-packages/flask_admin/base.py", line 69, in inner
    return self._run_view(f, *args, **kwargs)
  File "/Users/AlexYang/anaconda3/lib/python3.6/site-packages/flask_admin/base.py", line 368, in _run_view
    return fn(self, *args, **kwargs)
TypeError: index() takes 0 positional arguments but 1 was given
2020-01-16 14:19:34,530 INFO: Mt Rainier startup [in /Users/AlexYang/mt.rainier-form/app/__init__.py:56]
2020-01-16 14:19:55,071 INFO: Mt Rainier startup [in /Users/AlexYang/mt.rainier-form/app/__init__.py:56]
2020-01-16 14:24:49,159 INFO: Mt Rainier startup [in /Users/AlexYang/mt.rainier-form/app/__init__.py:56]
2020-01-16 14:24:55,353 ERROR: Exception on /admin/patient registration/ [GET] [in /Users/AlexYang/anaconda3/lib/python3.6/site-packages/flask/app.py:1761]
Traceback (most recent call last):
  File "/Users/AlexYang/anaconda3/lib/python3.6/site-packages/flask/app.py", line 2292, in wsgi_app
    response = self.full_dispatch_request()
  File "/Users/AlexYang/anaconda3/lib/python3.6/site-packages/flask/app.py", line 1815, in full_dispatch_request
    rv = self.handle_user_exception(e)
  File "/Users/AlexYang/anaconda3/lib/python3.6/site-packages/flask/app.py", line 1718, in handle_user_exception
    reraise(exc_type, exc_value, tb)
  File "/Users/AlexYang/anaconda3/lib/python3.6/site-packages/flask/_compat.py", line 35, in reraise
    raise value
  File "/Users/AlexYang/anaconda3/lib/python3.6/site-packages/flask/app.py", line 1813, in full_dispatch_request
    rv = self.dispatch_request()
  File "/Users/AlexYang/anaconda3/lib/python3.6/site-packages/flask/app.py", line 1799, in dispatch_request
    return self.view_functions[rule.endpoint](**req.view_args)
  File "/Users/AlexYang/anaconda3/lib/python3.6/site-packages/flask_admin/base.py", line 69, in inner
    return self._run_view(f, *args, **kwargs)
  File "/Users/AlexYang/anaconda3/lib/python3.6/site-packages/flask_admin/base.py", line 368, in _run_view
    return fn(self, *args, **kwargs)
TypeError: index() takes 0 positional arguments but 1 was given
2020-01-16 14:25:41,480 INFO: Mt Rainier startup [in /Users/AlexYang/mt.rainier-form/app/__init__.py:56]
