2020-01-11 22:33:09,737 INFO: Mt Rainier startup [in /Users/AlexYang/mt.rainier-form/app/__init__.py:52]
2020-01-11 22:33:11,420 ERROR: Exception on /followup [GET] [in /Users/AlexYang/anaconda3/lib/python3.6/site-packages/flask/app.py:1761]
Traceback (most recent call last):
  File "/Users/AlexYang/anaconda3/lib/python3.6/site-packages/flask/app.py", line 2292, in wsgi_app
    response = self.full_dispatch_request()
  File "/Users/AlexYang/anaconda3/lib/python3.6/site-packages/flask/app.py", line 1815, in full_dispatch_request
    rv = self.handle_user_exception(e)
  File "/Users/AlexYang/anaconda3/lib/python3.6/site-packages/flask/app.py", line 1718, in handle_user_exception
    reraise(exc_type, exc_value, tb)
  File "/Users/AlexYang/anaconda3/lib/python3.6/site-packages/flask/_compat.py", line 35, in reraise
    raise value
  File "/Users/AlexYang/anaconda3/lib/python3.6/site-packages/flask/app.py", line 1813, in full_dispatch_request
    rv = self.dispatch_request()
  File "/Users/AlexYang/anaconda3/lib/python3.6/site-packages/flask/app.py", line 1799, in dispatch_request
    return self.view_functions[rule.endpoint](**req.view_args)
  File "/Users/AlexYang/anaconda3/lib/python3.6/site-packages/flask_login/utils.py", line 261, in decorated_view
    return func(*args, **kwargs)
  File "/Users/AlexYang/mt.rainier-form/app/main/routes.py", line 71, in followup
    f = FollowUpForm()
NameError: name 'FollowUpForm' is not defined
2020-01-11 22:33:13,682 ERROR: Exception on /followup [GET] [in /Users/AlexYang/anaconda3/lib/python3.6/site-packages/flask/app.py:1761]
Traceback (most recent call last):
  File "/Users/AlexYang/anaconda3/lib/python3.6/site-packages/flask/app.py", line 2292, in wsgi_app
    response = self.full_dispatch_request()
  File "/Users/AlexYang/anaconda3/lib/python3.6/site-packages/flask/app.py", line 1815, in full_dispatch_request
    rv = self.handle_user_exception(e)
  File "/Users/AlexYang/anaconda3/lib/python3.6/site-packages/flask/app.py", line 1718, in handle_user_exception
    reraise(exc_type, exc_value, tb)
  File "/Users/AlexYang/anaconda3/lib/python3.6/site-packages/flask/_compat.py", line 35, in reraise
    raise value
  File "/Users/AlexYang/anaconda3/lib/python3.6/site-packages/flask/app.py", line 1813, in full_dispatch_request
    rv = self.dispatch_request()
  File "/Users/AlexYang/anaconda3/lib/python3.6/site-packages/flask/app.py", line 1799, in dispatch_request
    return self.view_functions[rule.endpoint](**req.view_args)
  File "/Users/AlexYang/anaconda3/lib/python3.6/site-packages/flask_login/utils.py", line 261, in decorated_view
    return func(*args, **kwargs)
  File "/Users/AlexYang/mt.rainier-form/app/main/routes.py", line 71, in followup
    f = FollowUpForm()
NameError: name 'FollowUpForm' is not defined
2020-01-11 22:35:06,251 INFO: Mt Rainier startup [in /Users/AlexYang/mt.rainier-form/app/__init__.py:52]
2020-01-11 22:35:11,838 ERROR: Exception on /followup [GET] [in /Users/AlexYang/anaconda3/lib/python3.6/site-packages/flask/app.py:1761]
Traceback (most recent call last):
  File "/Users/AlexYang/anaconda3/lib/python3.6/site-packages/flask/app.py", line 2292, in wsgi_app
    response = self.full_dispatch_request()
  File "/Users/AlexYang/anaconda3/lib/python3.6/site-packages/flask/app.py", line 1815, in full_dispatch_request
    rv = self.handle_user_exception(e)
  File "/Users/AlexYang/anaconda3/lib/python3.6/site-packages/flask/app.py", line 1718, in handle_user_exception
    reraise(exc_type, exc_value, tb)
  File "/Users/AlexYang/anaconda3/lib/python3.6/site-packages/flask/_compat.py", line 35, in reraise
    raise value
  File "/Users/AlexYang/anaconda3/lib/python3.6/site-packages/flask/app.py", line 1813, in full_dispatch_request
    rv = self.dispatch_request()
  File "/Users/AlexYang/anaconda3/lib/python3.6/site-packages/flask/app.py", line 1799, in dispatch_request
    return self.view_functions[rule.endpoint](**req.view_args)
  File "/Users/AlexYang/anaconda3/lib/python3.6/site-packages/flask_login/utils.py", line 261, in decorated_view
    return func(*args, **kwargs)
  File "/Users/AlexYang/mt.rainier-form/app/main/routes.py", line 96, in followup
    return render_template('followup.html', title='Follow Up Form', form=f)
  File "/Users/AlexYang/anaconda3/lib/python3.6/site-packages/flask/templating.py", line 135, in render_template
    context, ctx.app)
  File "/Users/AlexYang/anaconda3/lib/python3.6/site-packages/flask/templating.py", line 117, in _render
    rv = template.render(context)
  File "/Users/AlexYang/anaconda3/lib/python3.6/site-packages/jinja2/asyncsupport.py", line 76, in render
    return original_render(self, *args, **kwargs)
  File "/Users/AlexYang/anaconda3/lib/python3.6/site-packages/jinja2/environment.py", line 1008, in render
    return self.environment.handle_exception(exc_info, True)
  File "/Users/AlexYang/anaconda3/lib/python3.6/site-packages/jinja2/environment.py", line 780, in handle_exception
    reraise(exc_type, exc_value, tb)
  File "/Users/AlexYang/anaconda3/lib/python3.6/site-packages/jinja2/_compat.py", line 37, in reraise
    raise value.with_traceback(tb)
  File "/Users/AlexYang/mt.rainier-form/app/templates/followup.html", line 2, in top-level template code
    {% import 'bootstrap/wtf.html' as wtf %}
  File "/Users/AlexYang/mt.rainier-form/app/templates/base.html", line 1, in top-level template code
    {% extends 'bootstrap/base.html' %}
  File "/Users/AlexYang/anaconda3/lib/python3.6/site-packages/flask_bootstrap/templates/bootstrap/base.html", line 1, in top-level template code
    {% block doc -%}
  File "/Users/AlexYang/anaconda3/lib/python3.6/site-packages/flask_bootstrap/templates/bootstrap/base.html", line 4, in block "doc"
    {%- block html %}
  File "/Users/AlexYang/anaconda3/lib/python3.6/site-packages/flask_bootstrap/templates/bootstrap/base.html", line 20, in block "html"
    {% block body -%}
  File "/Users/AlexYang/anaconda3/lib/python3.6/site-packages/flask_bootstrap/templates/bootstrap/base.html", line 23, in block "body"
    {% block content -%}
  File "/Users/AlexYang/mt.rainier-form/app/templates/base.html", line 55, in block "content"
    {% block app_content %}{% endblock %}
  File "/Users/AlexYang/mt.rainier-form/app/templates/followup.html", line 251, in block "app_content"
    <p>{{ form.submit() }}</p>
jinja2.exceptions.UndefinedError: 'app.main.forms.FollowUpForm object' has no attribute 'submit'
2020-01-11 22:35:36,138 INFO: Mt Rainier startup [in /Users/AlexYang/mt.rainier-form/app/__init__.py:52]
2020-01-11 22:39:11,435 INFO: Mt Rainier startup [in /Users/AlexYang/mt.rainier-form/app/__init__.py:52]
2020-01-11 22:42:38,981 INFO: Mt Rainier startup [in /Users/AlexYang/mt.rainier-form/app/__init__.py:52]
2020-01-11 22:46:09,851 ERROR: Exception on /followup [POST] [in /Users/AlexYang/anaconda3/lib/python3.6/site-packages/flask/app.py:1761]
Traceback (most recent call last):
  File "/Users/AlexYang/anaconda3/lib/python3.6/site-packages/flask/app.py", line 2292, in wsgi_app
    response = self.full_dispatch_request()
  File "/Users/AlexYang/anaconda3/lib/python3.6/site-packages/flask/app.py", line 1815, in full_dispatch_request
    rv = self.handle_user_exception(e)
  File "/Users/AlexYang/anaconda3/lib/python3.6/site-packages/flask/app.py", line 1718, in handle_user_exception
    reraise(exc_type, exc_value, tb)
  File "/Users/AlexYang/anaconda3/lib/python3.6/site-packages/flask/_compat.py", line 35, in reraise
    raise value
  File "/Users/AlexYang/anaconda3/lib/python3.6/site-packages/flask/app.py", line 1813, in full_dispatch_request
    rv = self.dispatch_request()
  File "/Users/AlexYang/anaconda3/lib/python3.6/site-packages/flask/app.py", line 1799, in dispatch_request
    return self.view_functions[rule.endpoint](**req.view_args)
  File "/Users/AlexYang/anaconda3/lib/python3.6/site-packages/flask_login/utils.py", line 261, in decorated_view
    return func(*args, **kwargs)
  File "/Users/AlexYang/mt.rainier-form/app/main/routes.py", line 73, in followup
    submit = FollowUp(patient_name=f.patient_name.data, overall_problem=f.overall_problem.data, headaches=f.headaches.data,
NameError: name 'FollowUp' is not defined
2020-01-11 22:46:24,432 ERROR: Exception on /followup [POST] [in /Users/AlexYang/anaconda3/lib/python3.6/site-packages/flask/app.py:1761]
Traceback (most recent call last):
  File "/Users/AlexYang/anaconda3/lib/python3.6/site-packages/flask/app.py", line 2292, in wsgi_app
    response = self.full_dispatch_request()
  File "/Users/AlexYang/anaconda3/lib/python3.6/site-packages/flask/app.py", line 1815, in full_dispatch_request
    rv = self.handle_user_exception(e)
  File "/Users/AlexYang/anaconda3/lib/python3.6/site-packages/flask/app.py", line 1718, in handle_user_exception
    reraise(exc_type, exc_value, tb)
  File "/Users/AlexYang/anaconda3/lib/python3.6/site-packages/flask/_compat.py", line 35, in reraise
    raise value
  File "/Users/AlexYang/anaconda3/lib/python3.6/site-packages/flask/app.py", line 1813, in full_dispatch_request
    rv = self.dispatch_request()
  File "/Users/AlexYang/anaconda3/lib/python3.6/site-packages/flask/app.py", line 1799, in dispatch_request
    return self.view_functions[rule.endpoint](**req.view_args)
  File "/Users/AlexYang/anaconda3/lib/python3.6/site-packages/flask_login/utils.py", line 261, in decorated_view
    return func(*args, **kwargs)
  File "/Users/AlexYang/mt.rainier-form/app/main/routes.py", line 73, in followup
    submit = FollowUp(patient_name=f.patient_name.data, overall_problem=f.overall_problem.data, headaches=f.headaches.data,
NameError: name 'FollowUp' is not defined
